<?xml version="1.0" ?>
<!-- =================================================================================== -->
<!-- |    This document was autogenerated by xacro from franka_ros/franka_description/robots/panda/panda.urdf.xacro | -->
<!-- |    EDITING THIS FILE BY HAND IS NOT RECOMMENDED                                 | -->
<!-- =================================================================================== -->
<robot name="panda">
  <!-- Load inertial properties. Property is implicitly passed to macros. -->
  <!-- <xacro:property name="inertial_config" value="/home/shonosukehida/work/PLDM_franka_emika_panda/franka_ros/franka_description/robots/common/inertial.yaml"/> -->
  <!-- <xacro:property name="inertial" value="${xacro.load_yaml(inertial_config)}"/> -->
  <!-- ============================================================== -->
  <!-- Macro to add an <inertial> tag based on yaml-load properties   -->
  <!--                                                                -->
  <!-- name:     Name of the robot link (without prefix)              -->
  <!-- inertial: Dictionary of inertia properties (see inertial.yaml) -->
  <!-- ============================================================== -->
  <!-- <xacro:macro name="inertial_props" params="name inertial:=^">
      <xacro:unless value="${name in inertial}">${xacro.warning('No inertia properties defined for: ' + name)}</xacro:unless>
      <xacro:if value="${name in inertial}">
        <xacro:property name="inertial" value="${inertial[name]}" lazy_eval="false" />
        <inertial>
          <origin rpy="${inertial.origin.rpy}" xyz="${inertial.origin.xyz}" />
          <mass value="${inertial.mass}" />
          <xacro:property name="I" value="${inertial.inertia}" />
          <inertia ixx="${I.xx}" ixy="${I.xy}" ixz="${I.xz}" iyy="${I.yy}" iyz="${I.yz}" izz="${I.zz}" />
        </inertial>
      </xacro:if>
  </xacro:macro> -->
  <!-- 以下、各関節定義 -->
  <joint name="panda_joint1" type="revolute">
    <origin rpy="0 0 0" xyz="0 0 0.333"/>
    <parent link="panda_link0"/>
    <child link="panda_link1"/>
    <axis xyz="0 0 1"/>
    <limit effort="87.0" lower="-2.8973" upper="2.8973" velocity="2.175"/>
  </joint>
  <joint name="panda_joint2" type="revolute">
    <origin rpy="-1.5707963 0 0" xyz="0 0 0"/>
    <parent link="panda_link1"/>
    <child link="panda_link2"/>
    <axis xyz="0 0 1"/>
    <limit effort="87.0" lower="-1.7628" upper="1.7628" velocity="2.175"/>
  </joint>
  <joint name="panda_joint3" type="revolute">
    <origin rpy="1.5707963 0 0" xyz="0 -0.316 0"/>
    <parent link="panda_link2"/>
    <child link="panda_link3"/>
    <axis xyz="0 0 1"/>
    <limit effort="87.0" lower="-2.8973" upper="2.8973" velocity="2.175"/>
  </joint>
  <joint name="panda_joint4" type="revolute">
    <origin rpy="1.5707963 0 0" xyz="0.0825 0 0"/>
    <parent link="panda_link3"/>
    <child link="panda_link4"/>
    <axis xyz="0 0 1"/>
    <limit effort="87.0" lower="-3.0718" upper="-0.0698" velocity="2.175"/>
  </joint>
  <joint name="panda_joint5" type="revolute">
    <origin rpy="-1.5707963 0 0" xyz="-0.0825 0.384 0"/>
    <parent link="panda_link4"/>
    <child link="panda_link5"/>
    <axis xyz="0 0 1"/>
    <limit effort="12.0" lower="-2.8973" upper="2.8973" velocity="2.61"/>
  </joint>
  <joint name="panda_joint6" type="revolute">
    <origin rpy="1.5707963 0 0" xyz="0 0 0"/>
    <parent link="panda_link5"/>
    <child link="panda_link6"/>
    <axis xyz="0 0 1"/>
    <limit effort="12.0" lower="-0.0175" upper="3.7525" velocity="2.61"/>
  </joint>
  <joint name="panda_joint7" type="revolute">
    <origin rpy="1.5707963 0 0" xyz="0.088 0 0"/>
    <parent link="panda_link6"/>
    <child link="panda_link7"/>
    <axis xyz="0 0 1"/>
    <limit effort="12.0" lower="-2.8973" upper="2.8973" velocity="2.61"/>
  </joint>
  <link name="panda_link8"/>
  <joint name="panda_joint8" type="fixed">
    <origin rpy="0 0 0" xyz="0 0 0.107"/>
    <parent link="panda_link7"/>
    <child link="panda_link8"/>
  </joint>

  <link name="panda_link0"/>
  <link name="panda_link1"/>
  <link name="panda_link2"/>
  <link name="panda_link3"/>
  <link name="panda_link4"/>
  <link name="panda_link5"/>
  <link name="panda_link6"/>
  <link name="panda_link7"/>
  <link name="panda_link8"/>

</robot>

